<?xml version='1.0'?>
<sdf version='1.6'>
  <model name='ugv'>
    <plugin name="controller" filename="libcontroller_plugin.so"/>
    <link name='chassis'>
      <pose frame=''>0 0 0 0 -0 0</pose>
      <inertial>
        <mass>0.71616</mass>
        <inertia>
          <ixx>0.003533056</ixx>
          <ixy>0</ixy>
          <ixz>0</ixz>
          <iyy>0.0024826880000000003</iyy>
          <iyz>0</iyz>
          <izz>0.005824768000000001</izz>
        </inertia>
      </inertial>
      <visual name='visual'>
        <geometry>
          <box>
            <size>0.2 0.24 0.04</size>
          </box>
        </geometry>
        <material>
          <ambient>0.3 0.3 0.3 1</ambient>
          <diffuse>0.7 0.7 0.7 1</diffuse>
          <specular>0.01 0.01 0.01 1</specular>
          <emissive>0 0 0 1</emissive>
        </material>
        <transparency>0</transparency>
      </visual>
      <collision name='collision'>
        <geometry>
          <box>
            <size>0.2 0.24 0.04</size>
          </box>
        </geometry>
      </collision>
      <sensor name='stereo_camera' type='multicamera'>
        <pose>0.07 0 0.115 0 0.5235987755982988 0</pose>
        <always_on>1</always_on>
        <update_rate>10</update_rate>
        <camera name="left">
          <save enabled="false">
            <path>/tmp/stereo_camera_left</path>
          </save>
          <horizontal_fov>1.047</horizontal_fov>
          <pose>0 0.05 0 0 0 0</pose>
          <image>
            <width>400</width>
            <height>400</height>
          </image>
          <clip>
            <near>0.1</near>
            <far>100</far>
          </clip>
          <!-- <noise>
            <type>gaussian</type>
            <mean>0.0</mean>
            <stddev>0.007</stddev>
          </noise> -->
        </camera>
        <camera name="right">
          <save enabled="false">
            <path>/tmp/stereo_camera_right</path>
          </save>
          <horizontal_fov>1.047</horizontal_fov>
          <pose>0 -0.05 0 0 0 0</pose>
          <image>
            <width>400</width>
            <height>400</height>
          </image>
          <clip>
            <near>0.1</near>
            <far>100</far>
          </clip>
          <!-- <noise>
            <type>gaussian</type>
            <mean>0.0</mean>
            <stddev>0.007</stddev>
          </noise> -->
        </camera>
      </sensor>
      <visual name='camera-visual'>
        <pose>0.07 0 0.115 0 0.5235987755982988 0</pose>
        <geometry>
          <box>
            <size>0.03 0.1 0.03</size>
          </box>
        </geometry>
        <material>
          <ambient>0.3 0.6 0.3 1</ambient>
          <diffuse>0.7 0.7 0.7 1</diffuse>
          <specular>0.01 0.01 0.01 1</specular>
          <emissive>0 0 0 1</emissive>
        </material>
        <transparency>0</transparency>
      </visual>
      <visual name='camera-pole-visual'>
        <pose>0.07 0 0.0575 0 -0 0</pose>
        <geometry>
          <box>
            <size>0.02142857142857143 0.02142857142857143 0.115</size>
          </box>
        </geometry>
        <material>
          <ambient>0.3 0.3 0.3 1</ambient>
          <diffuse>0.7 0.7 0.7 1</diffuse>
          <specular>0.01 0.01 0.01 1</specular>
          <emissive>0 0 0 1</emissive>
        </material>
        <transparency>0</transparency>
      </visual>
    </link>
    <link name='front-right-wheel'>
      <pose frame=''>0.1 -0.12 -0.025 0 -0 0</pose>
      <inertial>
        <mass>0.1953023432981655</mass>
        <inertia>
          <ixx>0.00019530234329816556</ixx>
          <ixy>0</ixy>
          <ixz>0</ixz>
          <iyy>0.00019530234329816556</iyy>
          <iyz>0</iyz>
          <izz>0.00019530234329816556</izz>
        </inertia>
      </inertial>
      <visual name='visual'>
        <geometry>
          <sphere>
            <radius>0.05</radius>
          </sphere>
        </geometry>
        <material>
          <ambient>0.3 0.3 0.6 1</ambient>
          <diffuse>0.7 0.7 0.7 1</diffuse>
          <specular>0.01 0.01 0.01 1</specular>
          <emissive>0 0 0 1</emissive>
        </material>
        <transparency>0</transparency>
      </visual>
      <collision name='collision'>
        <geometry>
          <sphere>
            <radius>0.05</radius>
          </sphere>
        </geometry>
      </collision>
      <visual name='front-right-wheel-leg1-visual'>
        <pose>0.027038987007807904 0 0.08321744517582594 0 -0 0</pose>
        <geometry>
          <sphere>
            <radius>0.005</radius>
          </sphere>
        </geometry>
        <material>
          <ambient>0.6 0.3 0.3 1</ambient>
          <diffuse>0.7 0.7 0.7 1</diffuse>
          <specular>0.01 0.01 0.01 1</specular>
          <emissive>0 0 0 1</emissive>
        </material>
        <transparency>0</transparency>
      </visual>
      <collision name='front-right-wheel-leg1-collision'>
        <pose>0.027038987007807904 0 0.08321744517582594 0 -0 0</pose>
        <geometry>
          <sphere>
            <radius>0.005</radius>
          </sphere>
        </geometry>
      </collision>
      <visual name='front-right-wheel-leg2-visual'>
        <pose>-0.0707889870078079 0 0.05143120957559141 0 -0 0</pose>
        <geometry>
          <sphere>
            <radius>0.005</radius>
          </sphere>
        </geometry>
        <material>
          <ambient>0.6 0.3 0.3 1</ambient>
          <diffuse>0.7 0.7 0.7 1</diffuse>
          <specular>0.01 0.01 0.01 1</specular>
          <emissive>0 0 0 1</emissive>
        </material>
        <transparency>0</transparency>
      </visual>
      <collision name='front-right-wheel-leg2-collision'>
        <pose>-0.0707889870078079 0 0.05143120957559141 0 -0 0</pose>
        <geometry>
          <sphere>
            <radius>0.005</radius>
          </sphere>
        </geometry>
      </collision>
      <visual name='front-right-wheel-leg3-visual'>
        <pose>-0.0707889870078079 0 -0.05143120957559139 0 -0 0</pose>
        <geometry>
          <sphere>
            <radius>0.005</radius>
          </sphere>
        </geometry>
        <material>
          <ambient>0.6 0.3 0.3 1</ambient>
          <diffuse>0.7 0.7 0.7 1</diffuse>
          <specular>0.01 0.01 0.01 1</specular>
          <emissive>0 0 0 1</emissive>
        </material>
        <transparency>0</transparency>
      </visual>
      <collision name='front-right-wheel-leg3-collision'>
        <pose>-0.0707889870078079 0 -0.05143120957559139 0 -0 0</pose>
        <geometry>
          <sphere>
            <radius>0.005</radius>
          </sphere>
        </geometry>
      </collision>
      <visual name='front-right-wheel-leg4-visual'>
        <pose>0.027038987007807887 0 -0.08321744517582595 0 -0 0</pose>
        <geometry>
          <sphere>
            <radius>0.005</radius>
          </sphere>
        </geometry>
        <material>
          <ambient>0.6 0.3 0.3 1</ambient>
          <diffuse>0.7 0.7 0.7 1</diffuse>
          <specular>0.01 0.01 0.01 1</specular>
          <emissive>0 0 0 1</emissive>
        </material>
        <transparency>0</transparency>
      </visual>
      <collision name='front-right-wheel-leg4-collision'>
        <pose>0.027038987007807887 0 -0.08321744517582595 0 -0 0</pose>
        <geometry>
          <sphere>
            <radius>0.005</radius>
          </sphere>
        </geometry>
      </collision>
      <visual name='front-right-wheel-leg5-visual'>
        <pose>0.08750000000000001 0 -2.1431318985078683e-17 0 -0 0</pose>
        <geometry>
          <sphere>
            <radius>0.005</radius>
          </sphere>
        </geometry>
        <material>
          <ambient>0.6 0.3 0.3 1</ambient>
          <diffuse>0.7 0.7 0.7 1</diffuse>
          <specular>0.01 0.01 0.01 1</specular>
          <emissive>0 0 0 1</emissive>
        </material>
        <transparency>0</transparency>
      </visual>
      <collision name='front-right-wheel-leg5-collision'>
        <pose>0.08750000000000001 0 -2.1431318985078683e-17 0 -0 0</pose>
        <geometry>
          <sphere>
            <radius>0.005</radius>
          </sphere>
        </geometry>
      </collision>
    </link>
    <link name='front-left-wheel'>
      <pose frame=''>0.1 0.12 -0.025 0 -0 0</pose>
      <inertial>
        <mass>0.1953023432981655</mass>
        <inertia>
          <ixx>0.00019530234329816556</ixx>
          <ixy>0</ixy>
          <ixz>0</ixz>
          <iyy>0.00019530234329816556</iyy>
          <iyz>0</iyz>
          <izz>0.00019530234329816556</izz>
        </inertia>
      </inertial>
      <visual name='visual'>
        <geometry>
          <sphere>
            <radius>0.05</radius>
          </sphere>
        </geometry>
        <material>
          <ambient>0.3 0.3 0.6 1</ambient>
          <diffuse>0.7 0.7 0.7 1</diffuse>
          <specular>0.01 0.01 0.01 1</specular>
          <emissive>0 0 0 1</emissive>
        </material>
        <transparency>0</transparency>
      </visual>
      <collision name='collision'>
        <geometry>
          <sphere>
            <radius>0.05</radius>
          </sphere>
        </geometry>
      </collision>
      <visual name='front-left-wheel-leg1-visual'>
        <pose>0.027038987007807904 0 0.08321744517582594 0 -0 0</pose>
        <geometry>
          <sphere>
            <radius>0.005</radius>
          </sphere>
        </geometry>
        <material>
          <ambient>0.6 0.3 0.3 1</ambient>
          <diffuse>0.7 0.7 0.7 1</diffuse>
          <specular>0.01 0.01 0.01 1</specular>
          <emissive>0 0 0 1</emissive>
        </material>
        <transparency>0</transparency>
      </visual>
      <collision name='front-left-wheel-leg1-collision'>
        <pose>0.027038987007807904 0 0.08321744517582594 0 -0 0</pose>
        <geometry>
          <sphere>
            <radius>0.005</radius>
          </sphere>
        </geometry>
      </collision>
      <visual name='front-left-wheel-leg2-visual'>
        <pose>-0.0707889870078079 0 0.05143120957559141 0 -0 0</pose>
        <geometry>
          <sphere>
            <radius>0.005</radius>
          </sphere>
        </geometry>
        <material>
          <ambient>0.6 0.3 0.3 1</ambient>
          <diffuse>0.7 0.7 0.7 1</diffuse>
          <specular>0.01 0.01 0.01 1</specular>
          <emissive>0 0 0 1</emissive>
        </material>
        <transparency>0</transparency>
      </visual>
      <collision name='front-left-wheel-leg2-collision'>
        <pose>-0.0707889870078079 0 0.05143120957559141 0 -0 0</pose>
        <geometry>
          <sphere>
            <radius>0.005</radius>
          </sphere>
        </geometry>
      </collision>
      <visual name='front-left-wheel-leg3-visual'>
        <pose>-0.0707889870078079 0 -0.05143120957559139 0 -0 0</pose>
        <geometry>
          <sphere>
            <radius>0.005</radius>
          </sphere>
        </geometry>
        <material>
          <ambient>0.6 0.3 0.3 1</ambient>
          <diffuse>0.7 0.7 0.7 1</diffuse>
          <specular>0.01 0.01 0.01 1</specular>
          <emissive>0 0 0 1</emissive>
        </material>
        <transparency>0</transparency>
      </visual>
      <collision name='front-left-wheel-leg3-collision'>
        <pose>-0.0707889870078079 0 -0.05143120957559139 0 -0 0</pose>
        <geometry>
          <sphere>
            <radius>0.005</radius>
          </sphere>
        </geometry>
      </collision>
      <visual name='front-left-wheel-leg4-visual'>
        <pose>0.027038987007807887 0 -0.08321744517582595 0 -0 0</pose>
        <geometry>
          <sphere>
            <radius>0.005</radius>
          </sphere>
        </geometry>
        <material>
          <ambient>0.6 0.3 0.3 1</ambient>
          <diffuse>0.7 0.7 0.7 1</diffuse>
          <specular>0.01 0.01 0.01 1</specular>
          <emissive>0 0 0 1</emissive>
        </material>
        <transparency>0</transparency>
      </visual>
      <collision name='front-left-wheel-leg4-collision'>
        <pose>0.027038987007807887 0 -0.08321744517582595 0 -0 0</pose>
        <geometry>
          <sphere>
            <radius>0.005</radius>
          </sphere>
        </geometry>
      </collision>
      <visual name='front-left-wheel-leg5-visual'>
        <pose>0.08750000000000001 0 -2.1431318985078683e-17 0 -0 0</pose>
        <geometry>
          <sphere>
            <radius>0.005</radius>
          </sphere>
        </geometry>
        <material>
          <ambient>0.6 0.3 0.3 1</ambient>
          <diffuse>0.7 0.7 0.7 1</diffuse>
          <specular>0.01 0.01 0.01 1</specular>
          <emissive>0 0 0 1</emissive>
        </material>
        <transparency>0</transparency>
      </visual>
      <collision name='front-left-wheel-leg5-collision'>
        <pose>0.08750000000000001 0 -2.1431318985078683e-17 0 -0 0</pose>
        <geometry>
          <sphere>
            <radius>0.005</radius>
          </sphere>
        </geometry>
      </collision>
    </link>
    <link name='back-right-wheel'>
      <pose frame=''>-0.1 -0.12 -0.025 0 -0 0</pose>
      <inertial>
        <mass>0.1953023432981655</mass>
        <inertia>
          <ixx>0.00019530234329816556</ixx>
          <ixy>0</ixy>
          <ixz>0</ixz>
          <iyy>0.00019530234329816556</iyy>
          <iyz>0</iyz>
          <izz>0.00019530234329816556</izz>
        </inertia>
      </inertial>
      <visual name='visual'>
        <geometry>
          <sphere>
            <radius>0.05</radius>
          </sphere>
        </geometry>
        <material>
          <ambient>0.3 0.3 0.6 1</ambient>
          <diffuse>0.7 0.7 0.7 1</diffuse>
          <specular>0.01 0.01 0.01 1</specular>
          <emissive>0 0 0 1</emissive>
        </material>
        <transparency>0</transparency>
      </visual>
      <collision name='collision'>
        <geometry>
          <sphere>
            <radius>0.05</radius>
          </sphere>
        </geometry>
      </collision>
      <visual name='back-right-wheel-leg1-visual'>
        <pose>0.027038987007807904 0 0.08321744517582594 0 -0 0</pose>
        <geometry>
          <sphere>
            <radius>0.005</radius>
          </sphere>
        </geometry>
        <material>
          <ambient>0.6 0.3 0.3 1</ambient>
          <diffuse>0.7 0.7 0.7 1</diffuse>
          <specular>0.01 0.01 0.01 1</specular>
          <emissive>0 0 0 1</emissive>
        </material>
        <transparency>0</transparency>
      </visual>
      <collision name='back-right-wheel-leg1-collision'>
        <pose>0.027038987007807904 0 0.08321744517582594 0 -0 0</pose>
        <geometry>
          <sphere>
            <radius>0.005</radius>
          </sphere>
        </geometry>
      </collision>
      <visual name='back-right-wheel-leg2-visual'>
        <pose>-0.0707889870078079 0 0.05143120957559141 0 -0 0</pose>
        <geometry>
          <sphere>
            <radius>0.005</radius>
          </sphere>
        </geometry>
        <material>
          <ambient>0.6 0.3 0.3 1</ambient>
          <diffuse>0.7 0.7 0.7 1</diffuse>
          <specular>0.01 0.01 0.01 1</specular>
          <emissive>0 0 0 1</emissive>
        </material>
        <transparency>0</transparency>
      </visual>
      <collision name='back-right-wheel-leg2-collision'>
        <pose>-0.0707889870078079 0 0.05143120957559141 0 -0 0</pose>
        <geometry>
          <sphere>
            <radius>0.005</radius>
          </sphere>
        </geometry>
      </collision>
      <visual name='back-right-wheel-leg3-visual'>
        <pose>-0.0707889870078079 0 -0.05143120957559139 0 -0 0</pose>
        <geometry>
          <sphere>
            <radius>0.005</radius>
          </sphere>
        </geometry>
        <material>
          <ambient>0.6 0.3 0.3 1</ambient>
          <diffuse>0.7 0.7 0.7 1</diffuse>
          <specular>0.01 0.01 0.01 1</specular>
          <emissive>0 0 0 1</emissive>
        </material>
        <transparency>0</transparency>
      </visual>
      <collision name='back-right-wheel-leg3-collision'>
        <pose>-0.0707889870078079 0 -0.05143120957559139 0 -0 0</pose>
        <geometry>
          <sphere>
            <radius>0.005</radius>
          </sphere>
        </geometry>
      </collision>
      <visual name='back-right-wheel-leg4-visual'>
        <pose>0.027038987007807887 0 -0.08321744517582595 0 -0 0</pose>
        <geometry>
          <sphere>
            <radius>0.005</radius>
          </sphere>
        </geometry>
        <material>
          <ambient>0.6 0.3 0.3 1</ambient>
          <diffuse>0.7 0.7 0.7 1</diffuse>
          <specular>0.01 0.01 0.01 1</specular>
          <emissive>0 0 0 1</emissive>
        </material>
        <transparency>0</transparency>
      </visual>
      <collision name='back-right-wheel-leg4-collision'>
        <pose>0.027038987007807887 0 -0.08321744517582595 0 -0 0</pose>
        <geometry>
          <sphere>
            <radius>0.005</radius>
          </sphere>
        </geometry>
      </collision>
      <visual name='back-right-wheel-leg5-visual'>
        <pose>0.08750000000000001 0 -2.1431318985078683e-17 0 -0 0</pose>
        <geometry>
          <sphere>
            <radius>0.005</radius>
          </sphere>
        </geometry>
        <material>
          <ambient>0.6 0.3 0.3 1</ambient>
          <diffuse>0.7 0.7 0.7 1</diffuse>
          <specular>0.01 0.01 0.01 1</specular>
          <emissive>0 0 0 1</emissive>
        </material>
        <transparency>0</transparency>
      </visual>
      <collision name='back-right-wheel-leg5-collision'>
        <pose>0.08750000000000001 0 -2.1431318985078683e-17 0 -0 0</pose>
        <geometry>
          <sphere>
            <radius>0.005</radius>
          </sphere>
        </geometry>
      </collision>
    </link>
    <link name='back-left-wheel'>
      <pose frame=''>-0.1 0.12 -0.025 0 -0 0</pose>
      <inertial>
        <mass>0.1953023432981655</mass>
        <inertia>
          <ixx>0.00019530234329816556</ixx>
          <ixy>0</ixy>
          <ixz>0</ixz>
          <iyy>0.00019530234329816556</iyy>
          <iyz>0</iyz>
          <izz>0.00019530234329816556</izz>
        </inertia>
      </inertial>
      <visual name='visual'>
        <geometry>
          <sphere>
            <radius>0.05</radius>
          </sphere>
        </geometry>
        <material>
          <ambient>0.3 0.3 0.6 1</ambient>
          <diffuse>0.7 0.7 0.7 1</diffuse>
          <specular>0.01 0.01 0.01 1</specular>
          <emissive>0 0 0 1</emissive>
        </material>
        <transparency>0</transparency>
      </visual>
      <collision name='collision'>
        <geometry>
          <sphere>
            <radius>0.05</radius>
          </sphere>
        </geometry>
      </collision>
      <visual name='back-left-wheel-leg1-visual'>
        <pose>0.027038987007807904 0 0.08321744517582594 0 -0 0</pose>
        <geometry>
          <sphere>
            <radius>0.005</radius>
          </sphere>
        </geometry>
        <material>
          <ambient>0.6 0.3 0.3 1</ambient>
          <diffuse>0.7 0.7 0.7 1</diffuse>
          <specular>0.01 0.01 0.01 1</specular>
          <emissive>0 0 0 1</emissive>
        </material>
        <transparency>0</transparency>
      </visual>
      <collision name='back-left-wheel-leg1-collision'>
        <pose>0.027038987007807904 0 0.08321744517582594 0 -0 0</pose>
        <geometry>
          <sphere>
            <radius>0.005</radius>
          </sphere>
        </geometry>
      </collision>
      <visual name='back-left-wheel-leg2-visual'>
        <pose>-0.0707889870078079 0 0.05143120957559141 0 -0 0</pose>
        <geometry>
          <sphere>
            <radius>0.005</radius>
          </sphere>
        </geometry>
        <material>
          <ambient>0.6 0.3 0.3 1</ambient>
          <diffuse>0.7 0.7 0.7 1</diffuse>
          <specular>0.01 0.01 0.01 1</specular>
          <emissive>0 0 0 1</emissive>
        </material>
        <transparency>0</transparency>
      </visual>
      <collision name='back-left-wheel-leg2-collision'>
        <pose>-0.0707889870078079 0 0.05143120957559141 0 -0 0</pose>
        <geometry>
          <sphere>
            <radius>0.005</radius>
          </sphere>
        </geometry>
      </collision>
      <visual name='back-left-wheel-leg3-visual'>
        <pose>-0.0707889870078079 0 -0.05143120957559139 0 -0 0</pose>
        <geometry>
          <sphere>
            <radius>0.005</radius>
          </sphere>
        </geometry>
        <material>
          <ambient>0.6 0.3 0.3 1</ambient>
          <diffuse>0.7 0.7 0.7 1</diffuse>
          <specular>0.01 0.01 0.01 1</specular>
          <emissive>0 0 0 1</emissive>
        </material>
        <transparency>0</transparency>
      </visual>
      <collision name='back-left-wheel-leg3-collision'>
        <pose>-0.0707889870078079 0 -0.05143120957559139 0 -0 0</pose>
        <geometry>
          <sphere>
            <radius>0.005</radius>
          </sphere>
        </geometry>
      </collision>
      <visual name='back-left-wheel-leg4-visual'>
        <pose>0.027038987007807887 0 -0.08321744517582595 0 -0 0</pose>
        <geometry>
          <sphere>
            <radius>0.005</radius>
          </sphere>
        </geometry>
        <material>
          <ambient>0.6 0.3 0.3 1</ambient>
          <diffuse>0.7 0.7 0.7 1</diffuse>
          <specular>0.01 0.01 0.01 1</specular>
          <emissive>0 0 0 1</emissive>
        </material>
        <transparency>0</transparency>
      </visual>
      <collision name='back-left-wheel-leg4-collision'>
        <pose>0.027038987007807887 0 -0.08321744517582595 0 -0 0</pose>
        <geometry>
          <sphere>
            <radius>0.005</radius>
          </sphere>
        </geometry>
      </collision>
      <visual name='back-left-wheel-leg5-visual'>
        <pose>0.08750000000000001 0 -2.1431318985078683e-17 0 -0 0</pose>
        <geometry>
          <sphere>
            <radius>0.005</radius>
          </sphere>
        </geometry>
        <material>
          <ambient>0.6 0.3 0.3 1</ambient>
          <diffuse>0.7 0.7 0.7 1</diffuse>
          <specular>0.01 0.01 0.01 1</specular>
          <emissive>0 0 0 1</emissive>
        </material>
        <transparency>0</transparency>
      </visual>
      <collision name='back-left-wheel-leg5-collision'>
        <pose>0.08750000000000001 0 -2.1431318985078683e-17 0 -0 0</pose>
        <geometry>
          <sphere>
            <radius>0.005</radius>
          </sphere>
        </geometry>
      </collision>
    </link>
    <joint name='front-right-wheel-joint' type='revolute'>
      <parent>chassis</parent>
      <child>front-right-wheel</child>
      <pose frame=''>0 0 0 0 -0 0</pose>
      <axis>
        <xyz>0 1 0</xyz>
      </axis>
    </joint>
    <joint name='front-left-wheel-joint' type='revolute'>
      <parent>chassis</parent>
      <child>front-left-wheel</child>
      <pose frame=''>0 0 0 0 -0 0</pose>
      <axis>
        <xyz>0 1 0</xyz>
      </axis>
    </joint>
    <joint name='back-right-wheel-joint' type='revolute'>
      <parent>chassis</parent>
      <child>back-right-wheel</child>
      <pose frame=''>0 0 0 0 -0 0</pose>
      <axis>
        <xyz>0 1 0</xyz>
      </axis>
    </joint>
    <joint name='back-left-wheel-joint' type='revolute'>
      <parent>chassis</parent>
      <child>back-left-wheel</child>
      <pose frame=''>0 0 0 0 -0 0</pose>
      <axis>
        <xyz>0 1 0</xyz>
      </axis>
    </joint>
  </model>
</sdf>
