<?xml version='1.0'?>
<sdf version='1.6'>
  <model name='ugv-rb'>
    <plugin name="controller" filename="libcontroller_plugin.so"/>
    <link name='chassis'>
      <pose frame=''>0 0 0 0 -0 0</pose>
      <inertial>
        <mass>0.71616</mass>
        <inertia>
          <ixx>0.003533056</ixx>
          <ixy>0</ixy>
          <ixz>0</ixz>
          <iyy>0.0024826880000000003</iyy>
          <iyz>0</iyz>
          <izz>0.005824768000000001</izz>
        </inertia>
      </inertial>
      <visual name='visual'>
        <geometry>
          <box>
            <size>0.2 0.24 0.04</size>
          </box>
        </geometry>
        <material>
          <ambient>0.3 0.3 0.3 1</ambient>
          <diffuse>0.7 0.7 0.7 1</diffuse>
          <specular>0.01 0.01 0.01 1</specular>
          <emissive>0 0 0 1</emissive>
        </material>
        <transparency>0</transparency>
      </visual>
      <collision name='collision'>
        <geometry>
          <box>
            <size>0.2 0.24 0.04</size>
          </box>
        </geometry>
      </collision>
    </link>
    <link name='camera'>
      <pose frame=''>0 0 0.125 0 0.5235987755982988 0</pose>
      <inertial>
        <mass>0.04662500000000001</mass>
        <inertia>
          <ixx>1.942708333333334e-05</ixx>
          <ixy>0</ixy>
          <ixz>0</ixz>
          <iyy>1.942708333333334e-05</iyy>
          <iyz>0</iyz>
          <izz>1.942708333333334e-05</izz>
        </inertia>
      </inertial>
      <visual name='visual'>
        <geometry>
          <box>
            <size>0.05 0.05 0.05</size>
          </box>
        </geometry>
        <material>
          <ambient>0.3 0.3 0.3 1</ambient>
          <diffuse>0.7 0.7 0.7 1</diffuse>
          <specular>0.01 0.01 0.01 1</specular>
          <emissive>0 0 0 1</emissive>
        </material>
        <transparency>0</transparency>
      </visual>
      <collision name='collision'>
        <geometry>
          <box>
            <size>0.05 0.05 0.05</size>
          </box>
        </geometry>
      </collision>
      <sensor name='stereo_camera' type='multicamera'>
        <always_on>1</always_on>
        <update_rate>10</update_rate>
        <camera name="left">
          <save enabled="false">
            <path>/tmp/stereo_camera_left</path>
          </save>
          <horizontal_fov>1.047</horizontal_fov>
          <pose>0 0.05 0 0 0 0</pose>
          <image>
            <width>400</width>
            <height>400</height>
          </image>
          <clip>
            <near>0.1</near>
            <far>100</far>
          </clip>
          <!-- <noise>
            <type>gaussian</type>
            <mean>0.0</mean>
            <stddev>0.007</stddev>
          </noise> -->
        </camera>
        <camera name="right">
          <save enabled="false">
            <path>/tmp/stereo_camera_right</path>
          </save>
          <horizontal_fov>1.047</horizontal_fov>
          <pose>0 -0.05 0 0 0 0</pose>
          <image>
            <width>400</width>
            <height>400</height>
          </image>
          <clip>
            <near>0.1</near>
            <far>100</far>
          </clip>
          <!-- <noise>
            <type>gaussian</type>
            <mean>0.0</mean>
            <stddev>0.007</stddev>
          </noise> -->
        </camera>
      </sensor>
    </link>
    <link name='front-right-wheel'>
      <pose frame=''>0.1 -0.12 0 0 -0 0</pose>
      <inertial>
        <mass>0.1953023432981655</mass>
        <inertia>
          <ixx>0.00019530234329816556</ixx>
          <ixy>0</ixy>
          <ixz>0</ixz>
          <iyy>0.00019530234329816556</iyy>
          <iyz>0</iyz>
          <izz>0.00019530234329816556</izz>
        </inertia>
      </inertial>
      <visual name='visual'>
        <geometry>
          <sphere>
            <radius>0.05</radius>
          </sphere>
        </geometry>
        <material>
          <ambient>0.3 0.3 0.6 1</ambient>
          <diffuse>0.7 0.7 0.7 1</diffuse>
          <specular>0.01 0.01 0.01 1</specular>
          <emissive>0 0 0 1</emissive>
        </material>
        <transparency>0</transparency>
      </visual>
      <collision name='collision'>
        <geometry>
          <sphere>
            <radius>0.05</radius>
          </sphere>
        </geometry>
      </collision>
    </link>
    <link name='front-right-wheel-leg1'>
      <pose frame=''>0.06250000000000001 -0.12 0.0649519052838329 0 -0 0</pose>
      <inertial>
        <mass>0.00019530234329816546</mass>
        <inertia>
          <ixx>1.953023432981655e-09</ixx>
          <ixy>0</ixy>
          <ixz>0</ixz>
          <iyy>1.953023432981655e-09</iyy>
          <iyz>0</iyz>
          <izz>1.953023432981655e-09</izz>
        </inertia>
      </inertial>
      <visual name='visual'>
        <geometry>
          <sphere>
            <radius>0.005</radius>
          </sphere>
        </geometry>
        <material>
          <ambient>0.3 0.3 0.6 1</ambient>
          <diffuse>0.7 0.7 0.7 1</diffuse>
          <specular>0.01 0.01 0.01 1</specular>
          <emissive>0 0 0 1</emissive>
        </material>
        <transparency>0</transparency>
      </visual>
      <collision name='collision'>
        <geometry>
          <sphere>
            <radius>0.005</radius>
          </sphere>
        </geometry>
      </collision>
    </link>
    <link name='front-right-wheel-leg2'>
      <pose frame=''>0.062499999999999965 -0.12 -0.06495190528383289 0 -0 0</pose>
      <inertial>
        <mass>0.00019530234329816546</mass>
        <inertia>
          <ixx>1.953023432981655e-09</ixx>
          <ixy>0</ixy>
          <ixz>0</ixz>
          <iyy>1.953023432981655e-09</iyy>
          <iyz>0</iyz>
          <izz>1.953023432981655e-09</izz>
        </inertia>
      </inertial>
      <visual name='visual'>
        <geometry>
          <sphere>
            <radius>0.005</radius>
          </sphere>
        </geometry>
        <material>
          <ambient>0.3 0.3 0.6 1</ambient>
          <diffuse>0.7 0.7 0.7 1</diffuse>
          <specular>0.01 0.01 0.01 1</specular>
          <emissive>0 0 0 1</emissive>
        </material>
        <transparency>0</transparency>
      </visual>
      <collision name='collision'>
        <geometry>
          <sphere>
            <radius>0.005</radius>
          </sphere>
        </geometry>
      </collision>
    </link>
    <link name='front-right-wheel-leg3'>
      <pose frame=''>0.17500000000000002 -0.12 -1.83697019872103e-17 0 -0 0</pose>
      <inertial>
        <mass>0.00019530234329816546</mass>
        <inertia>
          <ixx>1.953023432981655e-09</ixx>
          <ixy>0</ixy>
          <ixz>0</ixz>
          <iyy>1.953023432981655e-09</iyy>
          <iyz>0</iyz>
          <izz>1.953023432981655e-09</izz>
        </inertia>
      </inertial>
      <visual name='visual'>
        <geometry>
          <sphere>
            <radius>0.005</radius>
          </sphere>
        </geometry>
        <material>
          <ambient>0.3 0.3 0.6 1</ambient>
          <diffuse>0.7 0.7 0.7 1</diffuse>
          <specular>0.01 0.01 0.01 1</specular>
          <emissive>0 0 0 1</emissive>
        </material>
        <transparency>0</transparency>
      </visual>
      <collision name='collision'>
        <geometry>
          <sphere>
            <radius>0.005</radius>
          </sphere>
        </geometry>
      </collision>
    </link>
    <link name='front-left-wheel'>
      <pose frame=''>0.1 0.12 0 0 -0 0</pose>
      <inertial>
        <mass>0.1953023432981655</mass>
        <inertia>
          <ixx>0.00019530234329816556</ixx>
          <ixy>0</ixy>
          <ixz>0</ixz>
          <iyy>0.00019530234329816556</iyy>
          <iyz>0</iyz>
          <izz>0.00019530234329816556</izz>
        </inertia>
      </inertial>
      <visual name='visual'>
        <geometry>
          <sphere>
            <radius>0.05</radius>
          </sphere>
        </geometry>
        <material>
          <ambient>0.3 0.3 0.6 1</ambient>
          <diffuse>0.7 0.7 0.7 1</diffuse>
          <specular>0.01 0.01 0.01 1</specular>
          <emissive>0 0 0 1</emissive>
        </material>
        <transparency>0</transparency>
      </visual>
      <collision name='collision'>
        <geometry>
          <sphere>
            <radius>0.05</radius>
          </sphere>
        </geometry>
      </collision>
    </link>
    <link name='front-left-wheel-leg1'>
      <pose frame=''>0.06250000000000001 0.12 0.0649519052838329 0 -0 0</pose>
      <inertial>
        <mass>0.00019530234329816546</mass>
        <inertia>
          <ixx>1.953023432981655e-09</ixx>
          <ixy>0</ixy>
          <ixz>0</ixz>
          <iyy>1.953023432981655e-09</iyy>
          <iyz>0</iyz>
          <izz>1.953023432981655e-09</izz>
        </inertia>
      </inertial>
      <visual name='visual'>
        <geometry>
          <sphere>
            <radius>0.005</radius>
          </sphere>
        </geometry>
        <material>
          <ambient>0.3 0.3 0.6 1</ambient>
          <diffuse>0.7 0.7 0.7 1</diffuse>
          <specular>0.01 0.01 0.01 1</specular>
          <emissive>0 0 0 1</emissive>
        </material>
        <transparency>0</transparency>
      </visual>
      <collision name='collision'>
        <geometry>
          <sphere>
            <radius>0.005</radius>
          </sphere>
        </geometry>
      </collision>
    </link>
    <link name='front-left-wheel-leg2'>
      <pose frame=''>0.062499999999999965 0.12 -0.06495190528383289 0 -0 0</pose>
      <inertial>
        <mass>0.00019530234329816546</mass>
        <inertia>
          <ixx>1.953023432981655e-09</ixx>
          <ixy>0</ixy>
          <ixz>0</ixz>
          <iyy>1.953023432981655e-09</iyy>
          <iyz>0</iyz>
          <izz>1.953023432981655e-09</izz>
        </inertia>
      </inertial>
      <visual name='visual'>
        <geometry>
          <sphere>
            <radius>0.005</radius>
          </sphere>
        </geometry>
        <material>
          <ambient>0.3 0.3 0.6 1</ambient>
          <diffuse>0.7 0.7 0.7 1</diffuse>
          <specular>0.01 0.01 0.01 1</specular>
          <emissive>0 0 0 1</emissive>
        </material>
        <transparency>0</transparency>
      </visual>
      <collision name='collision'>
        <geometry>
          <sphere>
            <radius>0.005</radius>
          </sphere>
        </geometry>
      </collision>
    </link>
    <link name='front-left-wheel-leg3'>
      <pose frame=''>0.17500000000000002 0.12 -1.83697019872103e-17 0 -0 0</pose>
      <inertial>
        <mass>0.00019530234329816546</mass>
        <inertia>
          <ixx>1.953023432981655e-09</ixx>
          <ixy>0</ixy>
          <ixz>0</ixz>
          <iyy>1.953023432981655e-09</iyy>
          <iyz>0</iyz>
          <izz>1.953023432981655e-09</izz>
        </inertia>
      </inertial>
      <visual name='visual'>
        <geometry>
          <sphere>
            <radius>0.005</radius>
          </sphere>
        </geometry>
        <material>
          <ambient>0.3 0.3 0.6 1</ambient>
          <diffuse>0.7 0.7 0.7 1</diffuse>
          <specular>0.01 0.01 0.01 1</specular>
          <emissive>0 0 0 1</emissive>
        </material>
        <transparency>0</transparency>
      </visual>
      <collision name='collision'>
        <geometry>
          <sphere>
            <radius>0.005</radius>
          </sphere>
        </geometry>
      </collision>
    </link>
    <link name='back-right-wheel'>
      <pose frame=''>-0.1 -0.12 0 0 -0 0</pose>
      <inertial>
        <mass>0.1953023432981655</mass>
        <inertia>
          <ixx>0.00019530234329816556</ixx>
          <ixy>0</ixy>
          <ixz>0</ixz>
          <iyy>0.00019530234329816556</iyy>
          <iyz>0</iyz>
          <izz>0.00019530234329816556</izz>
        </inertia>
      </inertial>
      <visual name='visual'>
        <geometry>
          <sphere>
            <radius>0.05</radius>
          </sphere>
        </geometry>
        <material>
          <ambient>0.3 0.3 0.6 1</ambient>
          <diffuse>0.7 0.7 0.7 1</diffuse>
          <specular>0.01 0.01 0.01 1</specular>
          <emissive>0 0 0 1</emissive>
        </material>
        <transparency>0</transparency>
      </visual>
      <collision name='collision'>
        <geometry>
          <sphere>
            <radius>0.05</radius>
          </sphere>
        </geometry>
      </collision>
    </link>
    <link name='back-right-wheel-leg1'>
      <pose frame=''>-0.1375 -0.12 0.0649519052838329 0 -0 0</pose>
      <inertial>
        <mass>0.00019530234329816546</mass>
        <inertia>
          <ixx>1.953023432981655e-09</ixx>
          <ixy>0</ixy>
          <ixz>0</ixz>
          <iyy>1.953023432981655e-09</iyy>
          <iyz>0</iyz>
          <izz>1.953023432981655e-09</izz>
        </inertia>
      </inertial>
      <visual name='visual'>
        <geometry>
          <sphere>
            <radius>0.005</radius>
          </sphere>
        </geometry>
        <material>
          <ambient>0.3 0.3 0.6 1</ambient>
          <diffuse>0.7 0.7 0.7 1</diffuse>
          <specular>0.01 0.01 0.01 1</specular>
          <emissive>0 0 0 1</emissive>
        </material>
        <transparency>0</transparency>
      </visual>
      <collision name='collision'>
        <geometry>
          <sphere>
            <radius>0.005</radius>
          </sphere>
        </geometry>
      </collision>
    </link>
    <link name='back-right-wheel-leg2'>
      <pose frame=''>-0.13750000000000004 -0.12 -0.06495190528383289 0 -0 0</pose>
      <inertial>
        <mass>0.00019530234329816546</mass>
        <inertia>
          <ixx>1.953023432981655e-09</ixx>
          <ixy>0</ixy>
          <ixz>0</ixz>
          <iyy>1.953023432981655e-09</iyy>
          <iyz>0</iyz>
          <izz>1.953023432981655e-09</izz>
        </inertia>
      </inertial>
      <visual name='visual'>
        <geometry>
          <sphere>
            <radius>0.005</radius>
          </sphere>
        </geometry>
        <material>
          <ambient>0.3 0.3 0.6 1</ambient>
          <diffuse>0.7 0.7 0.7 1</diffuse>
          <specular>0.01 0.01 0.01 1</specular>
          <emissive>0 0 0 1</emissive>
        </material>
        <transparency>0</transparency>
      </visual>
      <collision name='collision'>
        <geometry>
          <sphere>
            <radius>0.005</radius>
          </sphere>
        </geometry>
      </collision>
    </link>
    <link name='back-right-wheel-leg3'>
      <pose frame=''>-0.024999999999999994 -0.12 -1.83697019872103e-17 0 -0 0</pose>
      <inertial>
        <mass>0.00019530234329816546</mass>
        <inertia>
          <ixx>1.953023432981655e-09</ixx>
          <ixy>0</ixy>
          <ixz>0</ixz>
          <iyy>1.953023432981655e-09</iyy>
          <iyz>0</iyz>
          <izz>1.953023432981655e-09</izz>
        </inertia>
      </inertial>
      <visual name='visual'>
        <geometry>
          <sphere>
            <radius>0.005</radius>
          </sphere>
        </geometry>
        <material>
          <ambient>0.3 0.3 0.6 1</ambient>
          <diffuse>0.7 0.7 0.7 1</diffuse>
          <specular>0.01 0.01 0.01 1</specular>
          <emissive>0 0 0 1</emissive>
        </material>
        <transparency>0</transparency>
      </visual>
      <collision name='collision'>
        <geometry>
          <sphere>
            <radius>0.005</radius>
          </sphere>
        </geometry>
      </collision>
    </link>
    <link name='back-left-wheel'>
      <pose frame=''>-0.1 0.12 0 0 -0 0</pose>
      <inertial>
        <mass>0.1953023432981655</mass>
        <inertia>
          <ixx>0.00019530234329816556</ixx>
          <ixy>0</ixy>
          <ixz>0</ixz>
          <iyy>0.00019530234329816556</iyy>
          <iyz>0</iyz>
          <izz>0.00019530234329816556</izz>
        </inertia>
      </inertial>
      <visual name='visual'>
        <geometry>
          <sphere>
            <radius>0.05</radius>
          </sphere>
        </geometry>
        <material>
          <ambient>0.3 0.3 0.6 1</ambient>
          <diffuse>0.7 0.7 0.7 1</diffuse>
          <specular>0.01 0.01 0.01 1</specular>
          <emissive>0 0 0 1</emissive>
        </material>
        <transparency>0</transparency>
      </visual>
      <collision name='collision'>
        <geometry>
          <sphere>
            <radius>0.05</radius>
          </sphere>
        </geometry>
      </collision>
    </link>
    <link name='back-left-wheel-leg1'>
      <pose frame=''>-0.1375 0.12 0.0649519052838329 0 -0 0</pose>
      <inertial>
        <mass>0.00019530234329816546</mass>
        <inertia>
          <ixx>1.953023432981655e-09</ixx>
          <ixy>0</ixy>
          <ixz>0</ixz>
          <iyy>1.953023432981655e-09</iyy>
          <iyz>0</iyz>
          <izz>1.953023432981655e-09</izz>
        </inertia>
      </inertial>
      <visual name='visual'>
        <geometry>
          <sphere>
            <radius>0.005</radius>
          </sphere>
        </geometry>
        <material>
          <ambient>0.3 0.3 0.6 1</ambient>
          <diffuse>0.7 0.7 0.7 1</diffuse>
          <specular>0.01 0.01 0.01 1</specular>
          <emissive>0 0 0 1</emissive>
        </material>
        <transparency>0</transparency>
      </visual>
      <collision name='collision'>
        <geometry>
          <sphere>
            <radius>0.005</radius>
          </sphere>
        </geometry>
      </collision>
    </link>
    <link name='back-left-wheel-leg2'>
      <pose frame=''>-0.13750000000000004 0.12 -0.06495190528383289 0 -0 0</pose>
      <inertial>
        <mass>0.00019530234329816546</mass>
        <inertia>
          <ixx>1.953023432981655e-09</ixx>
          <ixy>0</ixy>
          <ixz>0</ixz>
          <iyy>1.953023432981655e-09</iyy>
          <iyz>0</iyz>
          <izz>1.953023432981655e-09</izz>
        </inertia>
      </inertial>
      <visual name='visual'>
        <geometry>
          <sphere>
            <radius>0.005</radius>
          </sphere>
        </geometry>
        <material>
          <ambient>0.3 0.3 0.6 1</ambient>
          <diffuse>0.7 0.7 0.7 1</diffuse>
          <specular>0.01 0.01 0.01 1</specular>
          <emissive>0 0 0 1</emissive>
        </material>
        <transparency>0</transparency>
      </visual>
      <collision name='collision'>
        <geometry>
          <sphere>
            <radius>0.005</radius>
          </sphere>
        </geometry>
      </collision>
    </link>
    <link name='back-left-wheel-leg3'>
      <pose frame=''>-0.024999999999999994 0.12 -1.83697019872103e-17 0 -0 0</pose>
      <inertial>
        <mass>0.00019530234329816546</mass>
        <inertia>
          <ixx>1.953023432981655e-09</ixx>
          <ixy>0</ixy>
          <ixz>0</ixz>
          <iyy>1.953023432981655e-09</iyy>
          <iyz>0</iyz>
          <izz>1.953023432981655e-09</izz>
        </inertia>
      </inertial>
      <visual name='visual'>
        <geometry>
          <sphere>
            <radius>0.005</radius>
          </sphere>
        </geometry>
        <material>
          <ambient>0.3 0.3 0.6 1</ambient>
          <diffuse>0.7 0.7 0.7 1</diffuse>
          <specular>0.01 0.01 0.01 1</specular>
          <emissive>0 0 0 1</emissive>
        </material>
        <transparency>0</transparency>
      </visual>
      <collision name='collision'>
        <geometry>
          <sphere>
            <radius>0.005</radius>
          </sphere>
        </geometry>
      </collision>
    </link>
    <joint name='front-right-wheel-joint' type='revolute'>
      <parent>chassis</parent>
      <child>front-right-wheel</child>
      <pose frame=''>0 0 0 0 -0 0</pose>
      <axis>
        <xyz>0 1 0</xyz>
      </axis>
    </joint>
    <joint name='front-left-wheel-joint' type='revolute'>
      <parent>chassis</parent>
      <child>front-left-wheel</child>
      <pose frame=''>0 0 0 0 -0 0</pose>
      <axis>
        <xyz>0 1 0</xyz>
      </axis>
    </joint>
    <joint name='back-right-wheel-joint' type='revolute'>
      <parent>chassis</parent>
      <child>back-right-wheel</child>
      <pose frame=''>0 0 0 0 -0 0</pose>
      <axis>
        <xyz>0 1 0</xyz>
      </axis>
    </joint>
    <joint name='back-left-wheel-joint' type='revolute'>
      <parent>chassis</parent>
      <child>back-left-wheel</child>
      <pose frame=''>0 0 0 0 -0 0</pose>
      <axis>
        <xyz>0 1 0</xyz>
      </axis>
    </joint>
    <joint name='camera-joint' type='fixed'>
      <parent>chassis</parent>
      <child>camera</child>
    </joint>
    <joint name='front-right-wheel-leg1-joint' type='fixed'>
      <parent>front-right-wheel</parent>
      <child>front-right-wheel-leg1</child>
    </joint>
    <joint name='front-right-wheel-leg2-joint' type='fixed'>
      <parent>front-right-wheel</parent>
      <child>front-right-wheel-leg2</child>
    </joint>
    <joint name='front-right-wheel-leg3-joint' type='fixed'>
      <parent>front-right-wheel</parent>
      <child>front-right-wheel-leg3</child>
    </joint>
    <joint name='front-left-wheel-leg1-joint' type='fixed'>
      <parent>front-left-wheel</parent>
      <child>front-left-wheel-leg1</child>
    </joint>
    <joint name='front-left-wheel-leg2-joint' type='fixed'>
      <parent>front-left-wheel</parent>
      <child>front-left-wheel-leg2</child>
    </joint>
    <joint name='front-left-wheel-leg3-joint' type='fixed'>
      <parent>front-left-wheel</parent>
      <child>front-left-wheel-leg3</child>
    </joint>
    <joint name='back-right-wheel-leg1-joint' type='fixed'>
      <parent>back-right-wheel</parent>
      <child>back-right-wheel-leg1</child>
    </joint>
    <joint name='back-right-wheel-leg2-joint' type='fixed'>
      <parent>back-right-wheel</parent>
      <child>back-right-wheel-leg2</child>
    </joint>
    <joint name='back-right-wheel-leg3-joint' type='fixed'>
      <parent>back-right-wheel</parent>
      <child>back-right-wheel-leg3</child>
    </joint>
    <joint name='back-left-wheel-leg1-joint' type='fixed'>
      <parent>back-left-wheel</parent>
      <child>back-left-wheel-leg1</child>
    </joint>
    <joint name='back-left-wheel-leg2-joint' type='fixed'>
      <parent>back-left-wheel</parent>
      <child>back-left-wheel-leg2</child>
    </joint>
    <joint name='back-left-wheel-leg3-joint' type='fixed'>
      <parent>back-left-wheel</parent>
      <child>back-left-wheel-leg3</child>
    </joint>
  </model>
</sdf>
