<?xml version='1.0'?>





<sdf version='1.6'>
  <model name='ugv-rb'>





    <link name='chassis'>

      <pose frame=''>0 0 0 0 -0 0</pose>

      <inertial>
        <mass>0.71616</mass>
        <inertia>
          <ixx>0.003533056</ixx>
          <ixy>0</ixy>
          <ixz>0</ixz>
          <iyy>0.0024826880000000003</iyy>
          <iyz>0</iyz>
          <izz>0.005824768000000001</izz>
        </inertia>
      </inertial>

      <visual name='visual'>
        <geometry>
          <box>
            <size>0.2 0.24 0.04</size>
          </box>
        </geometry>
        <material>
          <ambient>0.3 0.3 0.3 1</ambient>
          <diffuse>0.7 0.7 0.7 1</diffuse>
          <specular>0.01 0.01 0.01 1</specular>
          <emissive>0 0 0 1</emissive>
        </material>
        <transparency>0</transparency>
      </visual>

      <collision name='collision'>
        <geometry>
          <box>
            <size>0.2 0.24 0.04</size>
          </box>
        </geometry>
      </collision>

    </link>





    <link name='front-right-wheel'>

      <pose frame=''>0.1 -0.12 0 0 -0 0</pose>

      <inertial>
        <mass>0.1953023432981655</mass>
        <inertia>
          <ixx>0.00019530234329816556</ixx>
          <ixy>0</ixy>
          <ixz>0</ixz>
          <iyy>0.00019530234329816556</iyy>
          <iyz>0</iyz>
          <izz>0.00019530234329816556</izz>
        </inertia>
      </inertial>

      <visual name='visual'>
        <geometry>
          <sphere>
            <radius>0.05</radius>
          </sphere>
        </geometry>
        <material>
          <ambient>0.3 0.3 0.6 1</ambient>
          <diffuse>0.7 0.7 0.7 1</diffuse>
          <specular>0.01 0.01 0.01 1</specular>
          <emissive>0 0 0 1</emissive>
        </material>
        <transparency>0</transparency>
      </visual>

      <collision name='collision'>
        <geometry>
          <sphere>
            <radius>0.05</radius>
          </sphere>
        </geometry>
      </collision>

    </link>





    <link name='front-right-wheel-leg1'>

      <pose frame=''>0.18437546221665874 -0.12 0.03996732420789099 0 -0 0</pose>

      <inertial>
        <mass>0.00019530234329816546</mass>
        <inertia>
          <ixx>1.953023432981655e-09</ixx>
          <ixy>0</ixy>
          <ixz>0</ixz>
          <iyy>1.953023432981655e-09</iyy>
          <iyz>0</iyz>
          <izz>1.953023432981655e-09</izz>
        </inertia>
      </inertial>

      <visual name='visual'>
        <geometry>
          <sphere>
            <radius>0.005</radius>
          </sphere>
        </geometry>
        <material>
          <ambient>0.3 0.3 0.6 1</ambient>
          <diffuse>0.7 0.7 0.7 1</diffuse>
          <specular>0.01 0.01 0.01 1</specular>
          <emissive>0 0 0 1</emissive>
        </material>
        <transparency>0</transparency>
      </visual>

      <collision name='collision'>
        <geometry>
          <sphere>
            <radius>0.005</radius>
          </sphere>
        </geometry>
      </collision>

    </link>





    <link name='front-right-wheel-leg2'>

      <pose frame=''>0.15487828682683807 -0.12 0.025994977970607507 0 -0 0</pose>

      <inertial>
        <mass>0.00019530234329816546</mass>
        <inertia>
          <ixx>1.953023432981655e-09</ixx>
          <ixy>0</ixy>
          <ixz>0</ixz>
          <iyy>1.953023432981655e-09</iyy>
          <iyz>0</iyz>
          <izz>1.953023432981655e-09</izz>
        </inertia>
      </inertial>

      <visual name='visual'>
        <geometry>
          <sphere>
            <radius>0.005</radius>
          </sphere>
        </geometry>
        <material>
          <ambient>0.3 0.3 0.6 1</ambient>
          <diffuse>0.7 0.7 0.7 1</diffuse>
          <specular>0.01 0.01 0.01 1</specular>
          <emissive>0 0 0 1</emissive>
        </material>
        <transparency>0</transparency>
      </visual>

      <collision name='collision'>
        <geometry>
          <sphere>
            <radius>0.005</radius>
          </sphere>
        </geometry>
      </collision>

    </link>





    <link name='front-right-wheel-leg3'>

      <pose frame=''>0.11310623918697993 -0.12 0.006208218562253646 0 -0 0</pose>

      <inertial>
        <mass>0.00019530234329816546</mass>
        <inertia>
          <ixx>1.953023432981655e-09</ixx>
          <ixy>0</ixy>
          <ixz>0</ixz>
          <iyy>1.953023432981655e-09</iyy>
          <iyz>0</iyz>
          <izz>1.953023432981655e-09</izz>
        </inertia>
      </inertial>

      <visual name='visual'>
        <geometry>
          <sphere>
            <radius>0.005</radius>
          </sphere>
        </geometry>
        <material>
          <ambient>0.3 0.3 0.6 1</ambient>
          <diffuse>0.7 0.7 0.7 1</diffuse>
          <specular>0.01 0.01 0.01 1</specular>
          <emissive>0 0 0 1</emissive>
        </material>
        <transparency>0</transparency>
      </visual>

      <collision name='collision'>
        <geometry>
          <sphere>
            <radius>0.005</radius>
          </sphere>
        </geometry>
      </collision>

    </link>





    <link name='front-left-wheel'>

      <pose frame=''>0.1 0.12 0 0 -0 0</pose>

      <inertial>
        <mass>0.1953023432981655</mass>
        <inertia>
          <ixx>0.00019530234329816556</ixx>
          <ixy>0</ixy>
          <ixz>0</ixz>
          <iyy>0.00019530234329816556</iyy>
          <iyz>0</iyz>
          <izz>0.00019530234329816556</izz>
        </inertia>
      </inertial>

      <visual name='visual'>
        <geometry>
          <sphere>
            <radius>0.05</radius>
          </sphere>
        </geometry>
        <material>
          <ambient>0.3 0.3 0.6 1</ambient>
          <diffuse>0.7 0.7 0.7 1</diffuse>
          <specular>0.01 0.01 0.01 1</specular>
          <emissive>0 0 0 1</emissive>
        </material>
        <transparency>0</transparency>
      </visual>

      <collision name='collision'>
        <geometry>
          <sphere>
            <radius>0.05</radius>
          </sphere>
        </geometry>
      </collision>

    </link>





    <link name='front-left-wheel-leg1'>

      <pose frame=''>0.18437546221665874 0.12 0.03996732420789099 0 -0 0</pose>

      <inertial>
        <mass>0.00019530234329816546</mass>
        <inertia>
          <ixx>1.953023432981655e-09</ixx>
          <ixy>0</ixy>
          <ixz>0</ixz>
          <iyy>1.953023432981655e-09</iyy>
          <iyz>0</iyz>
          <izz>1.953023432981655e-09</izz>
        </inertia>
      </inertial>

      <visual name='visual'>
        <geometry>
          <sphere>
            <radius>0.005</radius>
          </sphere>
        </geometry>
        <material>
          <ambient>0.3 0.3 0.6 1</ambient>
          <diffuse>0.7 0.7 0.7 1</diffuse>
          <specular>0.01 0.01 0.01 1</specular>
          <emissive>0 0 0 1</emissive>
        </material>
        <transparency>0</transparency>
      </visual>

      <collision name='collision'>
        <geometry>
          <sphere>
            <radius>0.005</radius>
          </sphere>
        </geometry>
      </collision>

    </link>





    <link name='front-left-wheel-leg2'>

      <pose frame=''>0.15487828682683807 0.12 0.025994977970607507 0 -0 0</pose>

      <inertial>
        <mass>0.00019530234329816546</mass>
        <inertia>
          <ixx>1.953023432981655e-09</ixx>
          <ixy>0</ixy>
          <ixz>0</ixz>
          <iyy>1.953023432981655e-09</iyy>
          <iyz>0</iyz>
          <izz>1.953023432981655e-09</izz>
        </inertia>
      </inertial>

      <visual name='visual'>
        <geometry>
          <sphere>
            <radius>0.005</radius>
          </sphere>
        </geometry>
        <material>
          <ambient>0.3 0.3 0.6 1</ambient>
          <diffuse>0.7 0.7 0.7 1</diffuse>
          <specular>0.01 0.01 0.01 1</specular>
          <emissive>0 0 0 1</emissive>
        </material>
        <transparency>0</transparency>
      </visual>

      <collision name='collision'>
        <geometry>
          <sphere>
            <radius>0.005</radius>
          </sphere>
        </geometry>
      </collision>

    </link>





    <link name='front-left-wheel-leg3'>

      <pose frame=''>0.11310623918697993 0.12 0.006208218562253646 0 -0 0</pose>

      <inertial>
        <mass>0.00019530234329816546</mass>
        <inertia>
          <ixx>1.953023432981655e-09</ixx>
          <ixy>0</ixy>
          <ixz>0</ixz>
          <iyy>1.953023432981655e-09</iyy>
          <iyz>0</iyz>
          <izz>1.953023432981655e-09</izz>
        </inertia>
      </inertial>

      <visual name='visual'>
        <geometry>
          <sphere>
            <radius>0.005</radius>
          </sphere>
        </geometry>
        <material>
          <ambient>0.3 0.3 0.6 1</ambient>
          <diffuse>0.7 0.7 0.7 1</diffuse>
          <specular>0.01 0.01 0.01 1</specular>
          <emissive>0 0 0 1</emissive>
        </material>
        <transparency>0</transparency>
      </visual>

      <collision name='collision'>
        <geometry>
          <sphere>
            <radius>0.005</radius>
          </sphere>
        </geometry>
      </collision>

    </link>





    <link name='back-right-wheel'>

      <pose frame=''>-0.1 -0.12 0 0 -0 0</pose>

      <inertial>
        <mass>0.1953023432981655</mass>
        <inertia>
          <ixx>0.00019530234329816556</ixx>
          <ixy>0</ixy>
          <ixz>0</ixz>
          <iyy>0.00019530234329816556</iyy>
          <iyz>0</iyz>
          <izz>0.00019530234329816556</izz>
        </inertia>
      </inertial>

      <visual name='visual'>
        <geometry>
          <sphere>
            <radius>0.05</radius>
          </sphere>
        </geometry>
        <material>
          <ambient>0.3 0.3 0.6 1</ambient>
          <diffuse>0.7 0.7 0.7 1</diffuse>
          <specular>0.01 0.01 0.01 1</specular>
          <emissive>0 0 0 1</emissive>
        </material>
        <transparency>0</transparency>
      </visual>

      <collision name='collision'>
        <geometry>
          <sphere>
            <radius>0.05</radius>
          </sphere>
        </geometry>
      </collision>

    </link>





    <link name='back-right-wheel-leg1'>

      <pose frame=''>-0.01562453778334126 -0.12 0.03996732420789099 0 -0 0</pose>

      <inertial>
        <mass>0.00019530234329816546</mass>
        <inertia>
          <ixx>1.953023432981655e-09</ixx>
          <ixy>0</ixy>
          <ixz>0</ixz>
          <iyy>1.953023432981655e-09</iyy>
          <iyz>0</iyz>
          <izz>1.953023432981655e-09</izz>
        </inertia>
      </inertial>

      <visual name='visual'>
        <geometry>
          <sphere>
            <radius>0.005</radius>
          </sphere>
        </geometry>
        <material>
          <ambient>0.3 0.3 0.6 1</ambient>
          <diffuse>0.7 0.7 0.7 1</diffuse>
          <specular>0.01 0.01 0.01 1</specular>
          <emissive>0 0 0 1</emissive>
        </material>
        <transparency>0</transparency>
      </visual>

      <collision name='collision'>
        <geometry>
          <sphere>
            <radius>0.005</radius>
          </sphere>
        </geometry>
      </collision>

    </link>





    <link name='back-right-wheel-leg2'>

      <pose frame=''>-0.04512171317316194 -0.12 0.025994977970607507 0 -0 0</pose>

      <inertial>
        <mass>0.00019530234329816546</mass>
        <inertia>
          <ixx>1.953023432981655e-09</ixx>
          <ixy>0</ixy>
          <ixz>0</ixz>
          <iyy>1.953023432981655e-09</iyy>
          <iyz>0</iyz>
          <izz>1.953023432981655e-09</izz>
        </inertia>
      </inertial>

      <visual name='visual'>
        <geometry>
          <sphere>
            <radius>0.005</radius>
          </sphere>
        </geometry>
        <material>
          <ambient>0.3 0.3 0.6 1</ambient>
          <diffuse>0.7 0.7 0.7 1</diffuse>
          <specular>0.01 0.01 0.01 1</specular>
          <emissive>0 0 0 1</emissive>
        </material>
        <transparency>0</transparency>
      </visual>

      <collision name='collision'>
        <geometry>
          <sphere>
            <radius>0.005</radius>
          </sphere>
        </geometry>
      </collision>

    </link>





    <link name='back-right-wheel-leg3'>

      <pose frame=''>-0.08689376081302008 -0.12 0.006208218562253646 0 -0 0</pose>

      <inertial>
        <mass>0.00019530234329816546</mass>
        <inertia>
          <ixx>1.953023432981655e-09</ixx>
          <ixy>0</ixy>
          <ixz>0</ixz>
          <iyy>1.953023432981655e-09</iyy>
          <iyz>0</iyz>
          <izz>1.953023432981655e-09</izz>
        </inertia>
      </inertial>

      <visual name='visual'>
        <geometry>
          <sphere>
            <radius>0.005</radius>
          </sphere>
        </geometry>
        <material>
          <ambient>0.3 0.3 0.6 1</ambient>
          <diffuse>0.7 0.7 0.7 1</diffuse>
          <specular>0.01 0.01 0.01 1</specular>
          <emissive>0 0 0 1</emissive>
        </material>
        <transparency>0</transparency>
      </visual>

      <collision name='collision'>
        <geometry>
          <sphere>
            <radius>0.005</radius>
          </sphere>
        </geometry>
      </collision>

    </link>





    <link name='back-left-wheel'>

      <pose frame=''>-0.1 0.12 0 0 -0 0</pose>

      <inertial>
        <mass>0.1953023432981655</mass>
        <inertia>
          <ixx>0.00019530234329816556</ixx>
          <ixy>0</ixy>
          <ixz>0</ixz>
          <iyy>0.00019530234329816556</iyy>
          <iyz>0</iyz>
          <izz>0.00019530234329816556</izz>
        </inertia>
      </inertial>

      <visual name='visual'>
        <geometry>
          <sphere>
            <radius>0.05</radius>
          </sphere>
        </geometry>
        <material>
          <ambient>0.3 0.3 0.6 1</ambient>
          <diffuse>0.7 0.7 0.7 1</diffuse>
          <specular>0.01 0.01 0.01 1</specular>
          <emissive>0 0 0 1</emissive>
        </material>
        <transparency>0</transparency>
      </visual>

      <collision name='collision'>
        <geometry>
          <sphere>
            <radius>0.05</radius>
          </sphere>
        </geometry>
      </collision>

    </link>





    <link name='back-left-wheel-leg1'>

      <pose frame=''>-0.01562453778334126 0.12 0.03996732420789099 0 -0 0</pose>

      <inertial>
        <mass>0.00019530234329816546</mass>
        <inertia>
          <ixx>1.953023432981655e-09</ixx>
          <ixy>0</ixy>
          <ixz>0</ixz>
          <iyy>1.953023432981655e-09</iyy>
          <iyz>0</iyz>
          <izz>1.953023432981655e-09</izz>
        </inertia>
      </inertial>

      <visual name='visual'>
        <geometry>
          <sphere>
            <radius>0.005</radius>
          </sphere>
        </geometry>
        <material>
          <ambient>0.3 0.3 0.6 1</ambient>
          <diffuse>0.7 0.7 0.7 1</diffuse>
          <specular>0.01 0.01 0.01 1</specular>
          <emissive>0 0 0 1</emissive>
        </material>
        <transparency>0</transparency>
      </visual>

      <collision name='collision'>
        <geometry>
          <sphere>
            <radius>0.005</radius>
          </sphere>
        </geometry>
      </collision>

    </link>





    <link name='back-left-wheel-leg2'>

      <pose frame=''>-0.04512171317316194 0.12 0.025994977970607507 0 -0 0</pose>

      <inertial>
        <mass>0.00019530234329816546</mass>
        <inertia>
          <ixx>1.953023432981655e-09</ixx>
          <ixy>0</ixy>
          <ixz>0</ixz>
          <iyy>1.953023432981655e-09</iyy>
          <iyz>0</iyz>
          <izz>1.953023432981655e-09</izz>
        </inertia>
      </inertial>

      <visual name='visual'>
        <geometry>
          <sphere>
            <radius>0.005</radius>
          </sphere>
        </geometry>
        <material>
          <ambient>0.3 0.3 0.6 1</ambient>
          <diffuse>0.7 0.7 0.7 1</diffuse>
          <specular>0.01 0.01 0.01 1</specular>
          <emissive>0 0 0 1</emissive>
        </material>
        <transparency>0</transparency>
      </visual>

      <collision name='collision'>
        <geometry>
          <sphere>
            <radius>0.005</radius>
          </sphere>
        </geometry>
      </collision>

    </link>





    <link name='back-left-wheel-leg3'>

      <pose frame=''>-0.08689376081302008 0.12 0.006208218562253646 0 -0 0</pose>

      <inertial>
        <mass>0.00019530234329816546</mass>
        <inertia>
          <ixx>1.953023432981655e-09</ixx>
          <ixy>0</ixy>
          <ixz>0</ixz>
          <iyy>1.953023432981655e-09</iyy>
          <iyz>0</iyz>
          <izz>1.953023432981655e-09</izz>
        </inertia>
      </inertial>

      <visual name='visual'>
        <geometry>
          <sphere>
            <radius>0.005</radius>
          </sphere>
        </geometry>
        <material>
          <ambient>0.3 0.3 0.6 1</ambient>
          <diffuse>0.7 0.7 0.7 1</diffuse>
          <specular>0.01 0.01 0.01 1</specular>
          <emissive>0 0 0 1</emissive>
        </material>
        <transparency>0</transparency>
      </visual>

      <collision name='collision'>
        <geometry>
          <sphere>
            <radius>0.005</radius>
          </sphere>
        </geometry>
      </collision>

    </link>




    <joint name='front-right-wheel-joint' type='revolute'>
      <parent>chassis</parent>
      <child>front-right-wheel</child>
      <pose frame=''>0 0 0 0 -0 0</pose>
      <axis>
        <xyz>0 1 0</xyz>
      </axis>
    </joint>




    <joint name='front-left-wheel-joint' type='revolute'>
      <parent>chassis</parent>
      <child>front-left-wheel</child>
      <pose frame=''>0 0 0 0 -0 0</pose>
      <axis>
        <xyz>0 1 0</xyz>
      </axis>
    </joint>




    <joint name='back-right-wheel-joint' type='revolute'>
      <parent>chassis</parent>
      <child>back-right-wheel</child>
      <pose frame=''>0 0 0 0 -0 0</pose>
      <axis>
        <xyz>0 1 0</xyz>
      </axis>
    </joint>




    <joint name='back-left-wheel-joint' type='revolute'>
      <parent>chassis</parent>
      <child>back-left-wheel</child>
      <pose frame=''>0 0 0 0 -0 0</pose>
      <axis>
        <xyz>0 1 0</xyz>
      </axis>
    </joint>




  </model>
</sdf>
